Workbook

Sheet Synechococcus
A1: Table S5A: Protein categories and comparative proteomic analysis of Synechococcus sp. WH7803 proteins detected in SW axenic and R. pomeroyi co-cultures
K2: Axenic | T2: Co-culture
K3: A | N3: B | Q3: C | T3: A | W3: B | Z3: C | AC3: Axenic | AF3: Co-culture
A4: Accession | B4: Other reference | C4: Protein sequence | D4: Annotated function and designation | E4: Assigned function | F4: Additional information for category assignement | H4: Assigned category | I4: Fold change Axenic vs Co-culture | J4: Anova (p) | K4: SC | L4: Peak area | M4: NAF | N4: SC | O4: Peak area | P4: NAF | Q4: SC | R4: Peak area | S4: NAF | T4: SC | U4: Peak area | V4: NAF | W4: SC | X4: Peak area | Y4: NAF | Z4: SC | AA4: Peak area | AB4: NAF | AC4: A | AD4: B | AE4: C | AF4: A | AG4: B | AH4: C
A5: YP_001224119.1 | B5: SynWH7803_0396 | C5: MTVTPVADPTVGNLATPVNSSYFTKAFLNALPAYRPALSPNRCGLEVGMAHGFFLYGPFTICGPLRLTEYSTTAGLLATIGLVSILTVCLSIYGTAGNGPNVQPADATIDNPPADLFTKAGWAEFASGFWLGGCGGAAFAWFLTGTALVAPLVNIAGGVWSVN | D5: photosystem I reaction centre subunit XI | E5: Photosynthesis | I5: 1.6014397 | J5: 0.4733214 | K5: 2 | L5: 1915122.6 | M5: 0.0074928234 | N5: 0 | O5: 284999.69 | P5: 0.0011248125 | Q5: 2 | R5: 2345937.3 | S5: 0.0093131282 | T5: 1 | U5: 1591469.5 | V5: 0.0062161329 | W5: 1 | X5: 1394963.1 | Y5: 0.0053299497 | Z5: 2 | AA5: 4947982 | AB5: 0.019188299 | AC5: 34.924282 | AD5: 32.171468 | AE5: 33.606567 | AF5: 34.550282 | AG5: 33.121637 | AH5: 35.755884
A6: YP_001225926.1 | B6: SynWH7803_2203 | C6: MKRLLSWLTGLVVMAGLLFSLATPSGVQAADIRNVADDKIAERGDKVDLNNSSVRRFQQFPGMYPTLAGKIVLGGPYESVDDVLALDLTDRQKELFEKYRDNFTVTAPSIALNEGFDRINDGQYR | D6: photosystem II complex extrinsic protein precursor U | E6: Photosynthesis | H6: Replication, recombination and repair | I6: 1.357806 | J6: 0.10524198 | K6: 2 | L6: 2810594.4 | M6: 0.014339193 | N6: 2 | O6: 3568139.6 | P6: 0.018363488 | Q6: 2 | R6: 2445528.2 | S6: 0.012659876 | T6: 2 | U6: 3669666.9 | V6: 0.018690727 | W6: 2 | X6: 4176134 | Y6: 0.020807142 | Z6: 3 | AA6: 5131663.7 | AB6: 0.025950406 | AC6: Av= | AD6: 33.567439 | AF6: Av= | AG6: 34.475934 | AI6: Difference | AJ6: 102.70648
A7: YP_001224210.1 | B7: SynWH7803_0487 | C7: MPAIKFKRDFTHQDRVSFSFSNSRDAAKGSAEKGGQVASSPAEFKENQCGSMGIGSGPRIHEVCPFSAVNHSYAATGEGALSQAISAAYKQVFGNIGITDSQRLVSLEAFLRDGRITTRDFMAGLVKSELYKQTFFFAVSPMRGVELTVKHLLGRPPVSQSEVGAAIKMIADEGFDAFVDHLVRSEEYLETFGTDTVPYLRAFKSEARAYCSTFVSMAELAPANASAENVMYSGPLLVRRLVKTGLSVNAINPRAFDTSVEFSYTNAVGNTRNPAFRRIYGGKFAY | D7: phycobilisome linker polypeptide, C-phycoerythrin class II-associated | E7: Photosynthesis | I7: 1.2281488 | J7: 0.2512498 | K7: 42 | L7: 2.5568038e+08 | M7: 0.57012214 | N7: 31 | O7: 1.732449e+08 | P7: 0.38968869 | Q7: 35 | R7: 2.3052374e+08 | S7: 0.52157458 | T7: 37 | U7: 2.9079306e+08 | V7: 0.64733275 | W7: 35 | X7: 2.7475846e+08 | Y7: 0.59831936 | Z7: 39 | AA7: 3.1705208e+08 | AB7: 0.70074589 | AC7: Dev= | AD7: 1.3768244 | AF7: Dev= | AG7: 1.318696 | AI7: T-test | AJ7: 0.45553581
A8: YP_001224947.1 | B8: SynWH7803_1224 | C8: MFLSLLAITPASVSWTPKVALVMIICNVIAIAIGKATIKYPNEGAKMPSASFFGGMSHGAMLGCTSFGHLLGMGAILGLSTRGVF | D8: photosystem I reaction center subunit X | E8: Photosynthesis | I8: 1.1952669 | J8: 0.62404649 | K8: 4 | L8: 1426917 | M8: 0.010705731 | N8: 2 | O8: 437898.74 | P8: 0.0033141956 | Q8: 5 | R8: 2988481.5 | S8: 0.022750892 | T8: 3 | U8: 945025.98 | V8: 0.0070783885 | W8: 3 | X8: 2345017 | Y8: 0.017182054 | Z8: 5 | AA8: 3039915.8 | AB8: 0.022606775
A9: YP_001225247.1 | B9: SynWH7803_1524 | C9: MRVQLHSSLRTLCALFCVLMLTACSGAGAGLNSFKSPDGRYAFLYPSGWTRVAVTGGPQVVFHDLINSDETVSLVVSDVDPDNDLEGLGSAVAVGERLRREVIAPEGSGRVADLIEARERESDGHTFYDLEYAVHLQDRDRHELATVVVDRGRLYTLATSTNEARWTKVQGLFESVITSFTLLI | D9: photosystem II PsbP protein | E9: Photosynthesis | I9: 1.1642715 | J9: 0.23064866 | K9: 2 | L9: 2932717.5 | M9: 0.010164568 | N9: 1 | O9: 4142986.2 | P9: 0.014485018 | Q9: 2 | R9: 2767625.7 | S9: 0.009733215 | T9: 2 | U9: 3897076.8 | V9: 0.013484372 | W9: 2 | X9: 4335170.4 | Y9: 0.014673589 | Z9: 2 | AA9: 4154019.8 | AB9: 0.014270747
A10: YP_001225011.1 | B10: SynWH7803_1288 | C10: MSVVRDLILKADDDLRYPSSGELNSIVEFLGQGSLRLSVVRILSDNEKKIVDESARQLFSLRPEYVAPGGNAYGQKQRAQCLRDYSWYLRLVTYGVLAGSTEMIEQIGLIGAREMYNSLGVPMPGMVDAMRAMREASLVLLSDDQQRLAGPYFDFLIQGMQTST | D10: allophycocyanin subunit alpha | E10: Photosynthesis | I10: 1.0913372 | J10: 0.58133909 | K10: 10 | L10: 31991299 | M10: 0.1244012 | N10: 5 | O10: 17822505 | P10: 0.069911444 | Q10: 10 | R10: 29292553 | S10: 0.11557933 | T10: 8 | U10: 30155164 | V10: 0.11706509 | W10: 5 | X10: 31654046 | Y10: 0.12020801 | Z10: 6 | AA10: 32714304 | AB10: 0.12609266
A11: YP_001225751.1 | B11: SynWH7803_2028 | C11: MRLFKVTACIPSPEKVRTQRELQNTFFTKWVPYDSWFAEQQRIQKQGGRIIKVELCTGSRQVNVGN | D11: putative phycobilisome linker polypeptide | E11: Photosynthesis | I11: 1.0871924 | J11: 0.3546333 | K11: 5 | L11: 35316795 | M11: 0.34125095 | N11: 5 | O11: 34090219 | P11: 0.33228384 | Q11: 6 | R11: 33838438 | S11: 0.33176698 | T11: 6 | U11: 40407150 | V11: 0.38978386 | W11: 5 | X11: 38947123 | Y11: 0.36751871 | Z11: 6 | AA11: 42287856 | AB11: 0.40501183
A12: YP_001224228.1 | B12: SynWH7803_0505 | C12: MSLPLLDYPLSTQNNRVANITSRAEGFNQVVNQSTSSRDLLIEKAYRQIYFHAMKHDRDTCLESQFRAGSITMRDFVRQLLLSERFQQSYYQCNSNYRMVDQVIGRVLGRSVHNDGERRAWSIVIGEKGFTAFVDALLESDEYMNNFGYDRVPEQRARVLPGQPTGEIPIYQQFPRYGADWRDSLQDRAPSDQSQWQQLQASSTWVNGQPPALALKIWLGIAAVGAFELGRVILVIAVSMLRT | D12: phycobilisome rod-core linker polypeptide cpcG (L-RC 28.5) | E12: Photosynthesis | I12: 1.0724548 | J12: 0.5317108 | K12: 15 | L12: 74531853 | M12: 0.1956015 | N12: 10 | O12: 64047451 | P12: 0.16955825 | Q12: 13 | R12: 62616877 | S12: 0.16674465 | T12: 12 | U12: 71090227 | V12: 0.18625726 | W12: 11 | X12: 78277097 | Y12: 0.20062103 | Z12: 12 | AA12: 85964764 | AB12: 0.22361976
A13: YP_001224215.1 | B13: SynWH7803_0492 | C13: MKSVLTTVIGSADSGSRFPTSSDLESVQGSLQRAAARLEAAEKIAQNYDAIAQRAVDAVYTQYPNGATGRQPRQCATEGKEKCKRDFVHYLRLINYSLVVGGTGPLDELAINGQREVYKALSIDPGTYVAGFTQMRNDGCAPRDLSPQALTEYNAALDYVINSLA | D13: C-phycoerythrin class II alpha chain | E13: Photosynthesis | I13: 1.0691833 | J13: 0.42011271 | K13: 32 | L13: 1.0689857e+09 | M13: 4.1316589 | N13: 33 | O13: 1.042163e+09 | P13: 4.0632642 | Q13: 37 | R13: 1.0467917e+09 | S13: 4.105283 | T13: 35 | U13: 1.1816027e+09 | V13: 4.5592889 | W13: 29 | X13: 1.1813427e+09 | Y13: 4.4590255 | Z13: 29 | AA13: 1.2968023e+09 | AB13: 4.9680482
A14: YP_001223921.1 | B14: SynWH7803_0198 | C14: MSHAVKIYDTCIGCTQCVRACPLDVLEMVPWDGCKAGQIASSPRTEDCVGCKRCETACPTDFLSIRVYLGDETSRSMGLSY | D14: photosystem I subunit VII | E14: Photosynthesis | H14: Energy production and conversion | I14: 1.0660386 | J14: 0.68174361 | K14: 6 | L14: 15931682 | M14: 0.12543339 | N14: 4 | O14: 12230556 | P14: 0.097136968 | Q14: 5 | R14: 12883082 | S14: 0.10292042 | T14: 6 | U14: 18075620 | V14: 0.14207503 | W14: 4 | X14: 15207340 | Y14: 0.11692739 | Z14: 4 | AA14: 14313503 | AB14: 0.11170095
A15: YP_001225700.1 | B15: SynWH7803_1977 | C15: MASFLPNVRRSLSRLLIVLSAFAVLVIGTPAQAASWDAETLTVPADAEGSPVTFSEQQVKAGRKVFNTSCGTCHAGGITKTNHNVGLDPETLALATPARDNVAALVDYLQDPTSYDGEYSIADLHPSMRSRDLYPAMRDLTDEDLRLMSAYILVAPKVLGQEWGGGKIYF | D15: cytochrome c-550 | E15: Photosynthesis | I15: 1.0494618 | J15: 0.71570969 | K15: 4 | L15: 5893710.9 | M15: 0.022109373 | N15: 4 | O15: 5695446.3 | P15: 0.021552726 | Q15: 6 | R15: 4833704.7 | S15: 0.018399159 | T15: 5 | U15: 6904645.5 | V15: 0.025858423 | W15: 5 | X15: 5971343 | Y15: 0.021876161 | Z15: 5 | AA15: 5807889.4 | AB15: 0.021595606
A16: YP_001224242.1 | B16: SynWH7803_0519 | C16: MPVIRFVREGRDVECYPGENLRDVALREGIQLYGLKGQLGNCGGCGQCITCFVEVKGDQTAAASLTGRTAVEEAKLRRRPDSWRLACQALVERSVVILTRPQVSMSDQRRRIEAALNAPLPPGPTAWPVVETSEEEEEADADADDQSQLSNEAPATPGDEP | D16: ferredoxin | E16: Photosynthesis | I16: 1.0471657 | J16: 0.92296568 | K16: 2 | L16: 972151.14 | M16: 0.0038507422 | N16: 2 | O16: 1357391 | P16: 0.0054237849 | Q16: 2 | R16: 990304.35 | S16: 0.0039802431 | T16: 1 | U16: 1093223 | V16: 0.004323072 | W16: 1 | X16: 1815334.3 | Y16: 0.0070222896 | Z16: 0 | AA16: 890831.83 | AB16: 0.0034975653
A17: YP_001224203.1 | B17: SynWH7803_0480 | C17: MFDAFTKVVAQADARGQFISASEIDALAAMVSDSNKRLDAVNRISSNASTIVASAARQLFAQQPSLIAPGGNAYTSRRMAACLRDMEIILRYVTYASFAGDASVLEDRCLNGLRETYLALGTPGASVAAGVNLMKESALAIVNDRAGISAGDCASLSSEIGTYFDRAAAAVA | D17: R-phycocyanin II beta chain | E17: Photosynthesis | I17: 1.0432548 | J17: 0.6618127 | K17: 98 | L17: 1.0025128e+09 | M17: 3.7170467 | N17: 65 | O17: 8.1088145e+08 | P17: 3.0328594 | Q17: 92 | R17: 9.4349937e+08 | S17: 3.5496044 | T17: 74 | U17: 9.9040056e+08 | V17: 3.6659962 | W17: 66 | X17: 1.0414845e+09 | Y17: 3.7711377 | Z17: 81 | AA17: 1.0997711e+09 | AB17: 4.0417538
A18: YP_001225567.1 | B18: SynWH7803_1844 | C18: MRRLFALALSALLVFGFAPVAKADVAGLTPCAESARFQQRASAATTDQAKARFEMYSQAVCGEDGLPHLIVDGRWDHAGEFMLPGLMFLYIAGCIGWAGREYLKATRGTKEQYTKEIQIDLPLALKSCIAAATWPIAAFGELTSGKLLESDDKITVSPR | D18: photosystem I reaction centre PsaF protein | E18: Photosynthesis | I18: 1.0189176 | J18: 0.85852847 | K18: 19 | L18: 1.5235817e+08 | M18: 0.61108995 | N18: 10 | O18: 1.2240338e+08 | P18: 0.49524449 | Q18: 19 | R18: 1.5027309e+08 | S18: 0.61157664 | T18: 13 | U18: 1.5168205e+08 | V18: 0.60736065 | W18: 12 | X18: 1.4635134e+08 | Y18: 0.57325467 | Z18: 17 | AA18: 1.722182e+08 | AB18: 0.68466463
A19: YP_001225069.1 | B19: SynWH7803_1346 | C19: MRDAITGLIGRYDQLGRYLDRSAIDRIESYLDESAIRLKAVELINREAAELVREASQRLFQGDPELLLPGGNAYTTRRLAACLRDMDYFLRYASYALIAGDSTILNERVLNGLDDTYKSLGVPTGPTVRSMVLLADVLCERLLEEGVPSKSLDLVRAPFEHMASGLAASDVRQR | D19: allophycocyanin subunit beta | E19: Photosynthesis | I19: 1.0040543 | J19: 0.95075617 | K19: 9 | L19: 17819474 | M19: 0.065310373 | N19: 8 | O19: 19706375 | P19: 0.072858604 | Q19: 9 | R19: 17874894 | S19: 0.06647541 | T19: 10 | U19: 20501035 | V19: 0.075012926 | W19: 8 | X19: 20930106 | Y19: 0.074915242 | Z19: 9 | AA19: 18791093 | AB19: 0.068265108
A20: YP_001224226.1 | B20: SynWH7803_0503 | C20: MPFGPASLLGVERFSQESEAPLELIPGDDDAKKEQIIRAVYKQVLGNAYVMESERQLVAESQFKLGEISVRELVRRIAKSELYRGRFFDACSRYRYIELAFRHLLGRAPVDFDEMRAHAERLDNHGYDADIDSFLDSSDYQDTYGEWTVPFQRGWKTEACGTLQEFTWSFQLLRGNSSSSLKGDLSGISSKLGGNAYQNRPMAVVAPSSTEPGGWSFRPAKNLQDAPTRHGVGAGEQGKTYRVEVTAYSANNVRRISRYTRSNRVYFVPFDKLSEQFKRIHAEGGKISSITPVN | D20: phycobilisome linker polypeptide, C-phycoerythrin class I-associated | E20: Photosynthesis | I20: -1.001223 | J20: 0.93753501 | K20: 44 | L20: 5.1266322e+08 | M20: 1.1120424 | N20: 38 | O20: 3.7285098e+08 | P20: 0.81585188 | Q20: 46 | R20: 5.0528422e+08 | S20: 1.1121291 | T20: 44 | U20: 5.1491512e+08 | V20: 1.1150591 | W20: 38 | X20: 4.7967688e+08 | Y20: 1.0161305 | Z20: 41 | AA20: 5.1519139e+08 | AB20: 1.1076875
A21: YP_001224225.1 | B21: SynWH7803_0502 | C21: MSASKGFGAESLNDGPVSFSRNRNAASKPALSSGEFLRQSCASMKIAIGPRNHEDCPHGVTAQRYAPADSASLDAAINAAYRQVYGNAHVMDNERSVELEAQFCNGELNVRDFVRGLAKSNFYRARFFEGVAPQRGIELNLKHLLGRPPINQAEMSAHITLLASGGHDAVIDFIVDGAEYAEVFGDDVVPYTRSFTSAAGIPTNSFANMAALERGFALSDSAIGSRSQLSNNLARGTTAYIQLPSGFRSGVSPSSPSGAMAFAPKKRASSDGGDFAPIRNDAYVGFGLGQREQEVFQRCPGDTADTINGLIRATYRQVMGNPHLMESERAMSAESKFAEGYLSTRELVRAIALSPEYSRRFFETNAPYRFVELNFKHLLGRAPTSQAELSEHIQILANDGYEAEINSYLDSTEYQSTFGEDTVPYLRILSEQGRSQLAFNRHLSLAEGYAASDTVLNSSSLVTSVATNSVPSGWRTTTTRTNRNGAVAGSPSATTKRFRIVVNAQPRGGRQRTPNASYLVSGKDMTSQLKYIHARGGRIVSITEVM | D21: phycobilisome linker polypeptide, C-phycoerythrin-associated | E21: Photosynthesis | I21: -1.002713 | J21: 0.97972787 | K21: 79 | L21: 1.1120764e+09 | M21: 1.2989083 | N21: 60 | O21: 1.0175583e+09 | P21: 1.1989195 | Q21: 80 | R21: 1.1010917e+09 | S21: 1.3049614 | T21: 73 | U21: 1.1817217e+09 | V21: 1.3779459 | W21: 60 | X21: 1.1005362e+09 | Y21: 1.2553351 | Z21: 74 | AA21: 1.2078859e+09 | AB21: 1.398393
A22: YP_001225750.1 | B22: SynWH7803_2027 | C22: MQDAITNVINKSDVQGLYLDTTSMSSLEGYFASGELRVKAAATISANASSIIRDAVAKALLYSDITRPGGNMYTTRRYAACIRDLDYYLRYSTYAMLAGDTSILDERVLNGLKETYNSLGVPIGATVQAIQAMKEVTASLVGPDAGKEMGVYFDYICSGLGN | D22: allophycocyanin subunit beta | E22: Photosynthesis | I22: -1.0103148 | J22: 0.98972448 | K22: 62 | L22: 4.0041538e+08 | M22: 1.576276 | N22: 38 | O22: 3.2000587e+08 | P22: 1.2707681 | Q22: 55 | R22: 3.7668508e+08 | S22: 1.5046317 | T22: 41 | U22: 3.7615068e+08 | V22: 1.478279 | W22: 35 | X22: 3.8929661e+08 | Y22: 1.4966272 | Z22: 42 | AA22: 4.1671286e+08 | AB22: 1.62599
A23: YP_001224180.1 | B23: SynWH7803_0457 | C23: MTATALNGQLPQFIGSTGGLLNSAETEEKYAITWTSNSAQAFELPTGGAAMMNAGENIMYFARKEQCLALGTQLRTKFKPRIEDYKIYRIFPGGDTEYLHPSDGVFPEKVNEGRAMVGHNPRRIGQNTNPANIKFSGRNTFDA | D23: photosystem I reaction center subunit II | E23: Photosynthesis | I23: -1.0155845 | J23: 0.93487042 | K23: 21 | L23: 2.405928e+08 | M23: 1.072959 | N23: 14 | O23: 1.9982947e+08 | P23: 0.89897346 | Q23: 18 | R23: 2.4861443e+08 | S23: 1.1250118 | T23: 13 | U23: 2.4311275e+08 | V23: 1.0823838 | W23: 17 | X23: 2.3855658e+08 | Y23: 1.0389709 | Z23: 14 | AA23: 2.5458401e+08 | AB23: 1.1253589
A24: YP_001224202.1 | B24: SynWH7803_0479 | C24: MKTPLTEAVSAADSQGRFLSSTEVQAASGRFNRAAASLEAAKALSAKADALVNGAAQAVYNKFPYTTQMEGSNYSTTPEGKAKCSRDVGYYLRMITYCLVAGGTGPMDDYLIAGLDEINRTFELSPSWYVEALKYIKSNHGLSGDAATEANSYIDYAINALI | D24: R-phycocyanin II alpha chain | E24: Photosynthesis | I24: -1.0258144 | J24: 0.85302041 | K24: 38 | L24: 3.543363e+08 | M24: 1.394881 | N24: 25 | O24: 3.1107555e+08 | P24: 1.2353051 | Q24: 43 | R24: 3.1038051e+08 | S24: 1.2397846 | T24: 34 | U24: 3.5541852e+08 | V24: 1.3968012 | W24: 30 | X24: 3.4362348e+08 | Y24: 1.3210396 | Z24: 31 | AA24: 3.3516147e+08 | AB24: 1.3077811
A25: YP_001225574.1 | B25: SynWH7803_1851 | C25: MRRLLSPLFAALIVGVTVLTAPSTSWAYPFWAQQNYDSPREATGKIVCANCHLAQKLTQAEVPQSVLPDSVFKAVVKIPYDTSVPEIGADGSEVPLQVGAVVMLPDGFTLAPQDRWTDDIKEETEGVYFSEYSDDQPNVILVGPIPGDQHQEIVFPVLSPDPATDSNIHFGKYSIHVGGNRGRGQVYPTGEKSNNTVFTAPSTGTVRSIEAGENGASVVTIASADGTELSETVPVGPALIVSVGDAVEAGAPITNDPNVGGFGQLDTEVVLQNPVRIYGLLAFFAAVALAQIMLVLKKKQFEKVQAAEGV | D25: apocytochrome f | E25: Photosynthesis | I25: -1.0300444 | J25: 0.85909761 | K25: 7 | L25: 39595850 | M25: 0.081456267 | N25: 6 | O25: 31517736 | P25: 0.065405863 | Q25: 9 | R25: 39060475 | S25: 0.081534726 | T25: 9 | U25: 41984796 | V25: 0.086226334 | W25: 9 | X25: 39107705 | Y25: 0.078568534 | Z25: 8 | AA25: 35073671 | AB25: 0.071518023
A26: YP_001224076.1 | B26: SynWH7803_0353 | C26: MRFRPLLALVLAFCFTVVTACSGGAQAVDRSNVTYDDIRNTGKANDCPTLSDSARGSIDLTAGDAYELRGICMHPTQVFIKGEPANKRQEAQFVEGKILTRYTSSLDEVYGTLTVGEDSISFKEEGGIDFQPITVLIPGGEEFPFTFSSKNLDAVANGAAITTSTDFEGTYRTPSYRTSNFIDPKGRALTTGVDYPQGLIGLGGDYKELESENVKRYIDGQGVMSMSITKVDPETGEFAGVFSAIQPSDSDMGGREIVDVKINGELYGRLEEA | D26: photosystem II manganese-stabilizing protein PsbO | E26: Photosynthesis | I26: -1.0621973 | J26: 0.74212921 | K26: 35 | L26: 1.2711294e+08 | M26: 0.29693655 | N26: 20 | O26: 94317786 | P26: 0.22225642 | Q26: 30 | R26: 1.1712561e+08 | S26: 0.27762337 | T26: 25 | U26: 1.2078903e+08 | V26: 0.28169193 | W26: 25 | X26: 1.2013455e+08 | Y26: 0.27406481 | Z26: 25 | AA26: 1.0649426e+08 | AB26: 0.24658095
A27: YP_001224224.1 | B27: SynWH7803_0501 | C27: MTATISSLRCDANQDRSQASDIIRAAYRQVFGNRYLMELDVQPSIEALFINGDLSVQGLVTALAQSDTYRRLYLEANSPYRFVELNFKHLLGRPPRNQAEISEHVRLLADEGFDAEIASYTYSDEYLRNFGVDTVPYARTQTSVVGESTVAYRRNQAMDPGFAGFDADQASVLQVSLASNSNPNAAGTRKVVGGGNRFTVLWTSRVQLGAVRRSAQRSVVSYSSLSRTIQSIQAQGGRILSIANA | D27: phycobilisome linker polypeptide, C-phycoerythrin class I-associated | E27: Photosynthesis | I27: -1.0631508 | J27: 0.36767917 | K27: 44 | L27: 3.683401e+08 | M27: 0.95878105 | N27: 33 | O27: 3.6324034e+08 | P27: 0.9537869 | Q27: 47 | R27: 3.5154173e+08 | S27: 0.92849078 | T27: 30 | U27: 3.5581583e+08 | V27: 0.92463166 | W27: 30 | X27: 3.8480685e+08 | Y27: 0.97819337 | Z27: 38 | AA27: 3.6620064e+08 | AB27: 0.94481982
A28: YP_001223973.1 | B28: SynWH7803_0250 | C28: MPGMSSLLKPLIQLVLVACIGFGLGGCVTTRVPMATSSPWQVVDLNTDANPLDVAFTSADHGFLVGSNRLILETNDGGSSWNERSLDLPDEENFRLLSIAFEGDDGWIAGQPGLLMHTTDGGQNWTRLFLDTKLPGEPYLITALGPDSAELATNVGAVYRTRDGGGSWEAKVSDAAGAVRDLRRGADGSYVSVSSLGNFYATWTPGQDVWQVHQRVSSQRLQSIGYQPDGNLWMVARGAQIRLNDTAEDFESWSKPIIPITNGYGYMDMAWSKDGAIWAGGGNGTLLVSRDGGDSWERDPESRQAPTNFNRFVFNDSQGQEHAFLLGERGLMLHWTAVS | D28: Ycf48-like protein | E28: Photosynthesis | G28: Photosynthesis system II assembly factor | H28: General function prediction only | I28: -1.0647454 | J28: 0.67102317 | K28: 17 | L28: 50427582 | M28: 0.094864774 | N28: 12 | O28: 40064339 | P28: 0.076029415 | Q28: 14 | R28: 46053867 | S28: 0.087908971 | T28: 11 | U28: 48753828 | V28: 0.091562701 | W28: 10 | X28: 46834926 | Y28: 0.086043517 | Z28: 11 | AA28: 43952717 | AB28: 0.081956236
A29: YP_001225879.1 | B29: SynWH7803_2156 | C29: MALPLLQYAPTTQNNRVAAIRVASDENQRTRQMDISMDPENLKTVIESAYRQIFFHAFKSDREIFLESQLRSGQITVRDFIRGLCLSDTFKRSFYNLNSNYKVVRHLVEKVLGRKTHGKSEEIAWSIVIATKGVEGMVDALLDSEEYLNAFGYDTVPYQRNRVLPGRELGETPFNITTPRYDEYYRGILGFPQVVYTGTAKALPARAKRVRGGSPSDYLPWVRGLSNARGASPSGSADIDYLAKVPYRSVGR | D29: phycobilisome rod-core linker polypeptide cpcG (L-RC 27.8) | E29: Photosynthesis | I29: -1.075984 | J29: 0.25682715 | K29: 34 | L29: 5.264203e+08 | M29: 1.3321975 | N29: 26 | O29: 5.2543826e+08 | P29: 1.3413574 | Q29: 37 | R29: 5.3270094e+08 | S29: 1.3678854 | T29: 32 | U29: 5.2951993e+08 | V29: 1.3378005 | W29: 36 | X29: 5.3738492e+08 | Y29: 1.3281066 | Z29: 33 | AA29: 5.290454e+08 | AB29: 1.3270533
A30: YP_001225749.1 | B30: SynWH7803_2026 | C30: MSIVSNSIINADAEARYLSPGELDQIKAFVGGGQRRLRVAQVLSESRERIVKTAGGQLFQKRPDVISPGGNAYGEEMTATCLRDMDYYLRLVTYGVVAGDVTPIEEIGVIGARELYRSLGTPLEAMAEAVREMKTVAMSILSGADAEEAGFYFDYVVGALA | D30: allophycocyanin subunit alpha | E30: Photosynthesis | I30: -1.0803315 | J30: 0.33878002 | K30: 44 | L30: 5.9851976e+08 | M30: 2.3707685 | N30: 25 | O30: 5.9062971e+08 | P30: 2.3600042 | Q30: 44 | R30: 5.9287306e+08 | S30: 2.3828825 | T30: 39 | U30: 5.7908979e+08 | V30: 2.289969 | W30: 35 | X30: 5.7679861e+08 | Y30: 2.2312403 | Z30: 41 | AA30: 6.3128985e+08 | AB30: 2.478557
A31: YP_001224216.1 | B31: SynWH7803_0493 | C31: MLDAFSRQAVSADSSGSFIGGAQLNDLKAFIAEGNKRLDAVNAITANASCVVSDSVAGICCENTGLTAPNGGVYTNRKMAACLRDAEIIMRYVSYALLAGDASVLQDRCLNGLRETYAALGVPSGSAARAVAIMKASACAHITNTNNTTGEKRKMPVTEGDCNALSAEAASYFDMVISAIS | D31: C-phycoerythrin class II beta chain | E31: Photosynthesis | I31: -1.092061 | J31: 0.36722045 | K31: 105 | L31: 1.4196995e+09 | M31: 5.0021233 | N31: 66 | O31: 1.3209064e+09 | P31: 4.6947971 | Q31: 108 | R31: 1.301143e+09 | S31: 4.6517165 | T31: 91 | U31: 1.2978836e+09 | V31: 4.5652729 | W31: 88 | X31: 1.3208249e+09 | Y31: 4.5447989 | Z31: 86 | AA31: 1.4017187e+09 | AB31: 4.8952884
A32: YP_001225369.1 | B32: SynWH7803_1646 | C32: MAAELLEQPVLGSRRLSNILVAAMVTIGGVGFLFASLSSYLGRDLLPLGHPAGLVFVPQGLVMGLYSIAAALLATYLWAVIAIDVGSGSNRFDKQAGVITISRRGFRKPISVEIPLKDVQAVKVEVRDGFNTRRRVSLRVQGRRDMPLTRVGEPLPLAQLEQDGAELARFLGVNLEGL | D32: photosystem I assembly protein Ycf4 | E32: Photosynthesis | I32: -1.100239 | J32: 0.11809318 | K32: 5 | L32: 16911661 | M32: 0.060590257 | N32: 3 | O32: 19073954 | P32: 0.068935683 | Q32: 4 | R32: 17297033 | S32: 0.06288085 | T32: 4 | U32: 17215293 | V32: 0.061574938 | W32: 4 | X32: 19090318 | Y32: 0.066794571 | Z32: 4 | AA32: 16196464 | AB32: 0.057516994
A33: YP_001224241.1 | B33: SynWH7803_0518 | C33: MGLPWYRVHTVVINDPGRLLAVHLMHTALVAGWAGSMALYELAIFDPSDPVLNPMWRQGMFVMPFMARLGVTDSWGGWSITGATGVDPGFWSFEGVAAAHIVFSGLLMLAAIWHWTYWDLEIWQDPRTGEPALDLPKIFGIHLLLAGLGCFGFGAFHLTGVFGPGMWISDPYGITGHLEPVQPSWGPEGFNPFNPGGIVAHHIAAGIVGIIAGIFHITTRPPERLYKALRMGNIETVLASAIAAVFFAAFIVAGTMWYGAAATPIELFGPTRYQWDQNYFKTEINRRVQTAMDQGATASEAYASIPEKLAFYDYVGNSPAKGGLFRVGPMVNGDGLPTGWLGHISFTDKEGRDLQVRRLPNFFENFPVILEDSDGIVRGDIPFRRAEAKYSFEQQGITATVYGGALDGQTFTDPAEVKRLARKAQLGEAFEFDRETYNSDGTFRSSPRGWFTFGHATFALLFFFGHIWHGARTLYRDVFAGIDPDLGEQVEFGLFQKLGDRSTRRLPDGYVPPAGSPLS | D33: photosystem II P680 chlorophyll A apoprotein (CP-47 protein) | E33: Photosynthesis | I33: -1.1034478 | J33: 0.59460792 | K33: 43 | L33: 1.961389e+08 | M33: 0.2410088 | N33: 27 | O33: 1.5036017e+08 | P33: 0.1863755 | Q33: 42 | R33: 1.9824746e+08 | S33: 0.24717644 | T33: 40 | U33: 1.6788414e+08 | V33: 0.2059453 | W33: 28 | X33: 1.498398e+08 | Y33: 0.17980752 | Z33: 36 | AA33: 2.17334e+08 | AB33: 0.26470144
A34: YP_001224209.1 | B34: SynWH7803_0486 | C34: MKSVVTTVVTAADAAGRFPSQNDLEAVQGNIQRAAARLEAAEKLAAGLDAVTKEAGDACFNKYPYLKQPGEAGENQTKVDKCYRDLGHYLRLINYCLVVGGTGPLDEWGIAGAREVYRTLGLPTGPYVEALTYTRDRACAPRDMSPQALNEFKSYLDYVINALS | D34: C-phycoerythrin class I alpha chain | E34: Photosynthesis | I34: -1.1053482 | J34: 0.45793256 | K34: 40 | L34: 8.3848333e+08 | M34: 3.2605218 | N34: 37 | O34: 9.2064285e+08 | P34: 3.6113593 | Q34: 39 | R34: 7.2091649e+08 | S34: 2.8445129 | T34: 36 | U34: 8.844573e+08 | V34: 3.4335438 | W34: 34 | X34: 7.628196e+08 | Y34: 2.89685 | Z34: 34 | AA34: 7.7776145e+08 | AB34: 2.9977716
A35: YP_001224115.1 | B35: SynWH7803_0392 | C35: MATKFPSFSQGLAQDPTTRRIWYGIATAHDFESHDGMTEEKLYQKLFSTHFGHLAIIGLWVSGNLFHIAWQGNFEQWVADPLHVRPIAHAIWDPHFGQGAIDAFTQAGASSPVNIAYSGLYHWFYTIGMTTNAELYQGSIFMMILSAWALFAGWLHLQPKFRPSLAWFKNAESRLNHHLAVLFGFSSIAWTGHLVHVAIPESRGQHVGWDNFLNVMPHPAGLGPFFTGNWGVYAQNPDTMGQVFGSAEGSGTAILTFLGGFHPQTEALWLTDIAHHHLAIGVIFVIAGHMYRTNFGIGHSIREILEAHNPPQGTPGDLGAGHKGLYDTINNSLHFQLGLALASLGVVTSLVAQHMYAMPSYAFIAKDYTTQAALYTHHQYIAIFLMCGAFAHGAIFFIRDYDPEANKDNVLARMLEHKEAIISHLSWVSLFLGFHTLGLYVHNDVVVAFGTPEKQILVEPVFAQFVQAASGKAIYGFDVLLANTGGVAANANAAYMGGWMDAINGVRGSNDLFLPIGPGDFLVHHAIALGLHTTTLILVKGALDARGSKLMPDKKDFGYSFPCDGPGRGGTCDISAWDAFYLAVFWALNTVGWVTFYWHWKHLAIWQGNVAQFNESSTYLMGWFRDYLWLNSSQLINGYNPFGSNNLAVWAWMFLFGHLVWATGFMFLISWRGYWQELIETIVWAHQRTPLANLVGWRDKPVALSIVQARVVGLAHFTIGYILTYAAFLIASTSGKFG | D35: photosystem I P700 chlorophyll a apoprotein A2 | E35: Photosynthesis | I35: -1.1062567 | J35: 0.48133313 | K35: 32 | L35: 1.918571e+08 | M35: 0.16578989 | N35: 21 | O35: 1.5248266e+08 | P35: 0.13291912 | Q35: 33 | R35: 1.8027218e+08 | S35: 0.15806624 | T35: 26 | U35: 1.7873429e+08 | V35: 0.15419173 | W35: 23 | X35: 1.6606301e+08 | Y35: 0.14014079 | Z35: 27 | AA35: 1.7046353e+08 | AB35: 0.14600613
A36: YP_001225748.1 | B36: SynWH7803_2025 | C36: MTVTASSGSPRVSPQLYDTLPLSSVRQAEQQDRFPDGGELDSLITFFRSGNDRLEASRIIAANAESIVARAANRIFVGGTPLSFLESPLTTGEERRAGDDTPLAADQVAFAQSVRTFTGESATTKRGNFLTRLLDGSSGDADVRVVLPTGFNAISVAKYGPAFMRKSVRDMGWFLRYVGYALVAGDPSILSVNTRGLRDILLKNCSLTATNVALQEMRAASAQLLRELPEARRLTIDCFNVLLQELAVATPSTRQKPGSAVRQGLQLPAIYALAAESAQRFEMRPGLSGAEKAEIVKAAYRQVFERDIAKGYSQTPCRSEASQLVQGKISMREFIRALGKSKEYRTQFYGRFVNSRVVELAYRHFLGRGISSLEEFRKAFSIVSEQGLNGLVDVLVNSSEYAQTFGEETVPYLRDLGEEAQESAGWGSNRRLFRFSAPFEGAPQYVTLYASYRQPFGDQHVYGGGNDPVGNQYGAIFPSSTASVATRPAPFGYDTRRLLVSNGMAQPGQMDSPQFRGSRPRKVGPRVLRLQQIATGGAARPRRGGQPSIRNTESSTQAVIKAVYVQVLGTAGYAGERLSSEEARLENGDISLRDFVRSVARSNAFRRRYWEGLYITKAIEVMHRRLLGRPTFGRWEIDALFDTAARRGFYGLVDALIDGQDYKDCFGEDTVPYERFITPADLNTRRAPALRRPIDVTAVVDLAMGRRPDSVRNDRLRTTSDVTTRNLTGQTQTAAGQWRADLSSMPASNWSPLMRRRPQRSSTSPGSAQDTANSWSRTLDSRFTRTIQQDQGKTGLTAALQVGNALGFQRRTGLPAKLSLPVNPSESELREVADATYRQLLNRVPLESERLITSESRLRDGQIDLEGFVAAVATSEAFMERLSKMAPLRAATAAAMALVGRASTPAETSRFLIVRAESGQCAAVQELLDLRSKLGFESSEVPGLQGLSSQPGVTQPTLTRTASLYSGNAGLTPPTSQPL | D36: anchor polypeptide LCM | E36: Photosynthesis | I36: -1.1249093 | J36: 0.32988043 | K36: 116 | L36: 6.1064315e+08 | M36: 0.39777852 | N36: 95 | O36: 5.9095106e+08 | P36: 0.38832217 | Q36: 129 | R36: 6.3958864e+08 | S36: 0.42275119 | T36: 105 | U36: 5.9867101e+08 | V36: 0.38932753 | W36: 98 | X36: 5.1348651e+08 | Y36: 0.3266588 | Z36: 105 | AA36: 6.5422808e+08 | AB36: 0.42241805
A37: YP_001224114.1 | B37: SynWH7803_0391 | C37: MTISPPERGSTAKTQVEKVDNPATFELFGKPGHFDRALAKGPKTTTWVWNLHANAHDFDSHTSDLEEVSRKIFSAHFGHLAVIFIWLSGAFFHGARFSNFSGWLADPTHVKPSAQVVWPVFGQEILNGDMGAGFQGIQITSGLFHVWRAWGITNETQLMSLAIGALVMAGLMLNAGVFHYHKAAPKLEWFQNVESMLNHHLAGLLGLGSLSWTGHLLHVSLPTTKLMDAIDAGQPLVLNGKTIASVADIPLPHEFFNQDLLAQLYPGFGAGIGAFFSGNWAAYSDFLTFKGGLNPVTGSMWMSDIAHHHLAIAVLFIVAGHMYRTNWGIGHSIKEILEGQKGDPLLFPATKGHDGLFEFMTTSWHAQLAVNLAMLGSLSIIVAQHMYAMPPYAYMSIDYPTQIGLFTHHMWIGGFLIVGAAAHAAIAMIRDYDPAKHVDNVLDRVLKARDALISHLNWVCIWLGFHSFGLYIHNDTMRALGRPQDMFSDSAIQLKPVFAQWIQGLHAAAAGSTAPNALAGVSEVFNGSVVAVGGKVAAAPIPLGTADFMVHHIHAFTIHVTVLILLKGVLYARNSRLIPDKANLGFRFPCDGPGRGGTCQVSAWDHVFLGLFWMYNSLSIVIFHFSWKMQSDVWGTVNADGSVQHITNGNFANSAITINGWLRDFLWAQAAQVINSYGSNTSAYGLMFLGAHFVWAFSLMFLFSGRGYWQELIESIVWAHNKLKVAPAIQPRALSITQGRAVGVAHYLLGGIATTWAFFHAHILVVG | D37: photosystem I P700 chlorophyll a apoprotein A1 | E37: Photosynthesis | I37: -1.1278808 | J37: 0.19381851 | K37: 18 | L37: 1.076464e+08 | M37: 0.089503635 | N37: 16 | O37: 1.0732975e+08 | P37: 0.090021891 | Q37: 16 | R37: 1.0773315e+08 | S37: 0.090890976 | T37: 16 | U37: 1.0821863e+08 | V37: 0.089828932 | W37: 15 | X37: 98868853 | Y37: 0.080280883 | Z37: 16 | AA37: 1.0232804e+08 | AB37: 0.084332559
A38: YP_001224256.1 | B38: SynWH7803_0533 | C38: MANSSPVYDWFQERLEIQDIADDISSKYVPPHVNIFYCLGGITLVCFLIQFATGFAMTFYYKPTVAEAYSSVQYLMTDVSFGWLIRSVHRWSASMMVLMLILHVFRVYLTGGFKRPRELTWVTGVTMAVITVSFGVTGYSLPWDQVGYWAVKIVSGVPAAIPVVGDFMVELLRGGESVGQSTLTRFYSLHTFVMPWLLAVFMLMHFLMIRKQGISGPL | D38: cytochrome b6 | E38: Photosynthesis | H38: Energy production and conversion | I38: -1.1293246 | J38: 0.29290541 | K38: 13 | L38: 74538131 | M38: 0.21805123 | N38: 12 | O38: 68684012 | P38: 0.20268543 | Q38: 12 | R38: 79583540 | S38: 0.23622918 | T38: 12 | U38: 65928315 | V38: 0.19254181 | W38: 11 | X38: 66700060 | Y38: 0.19055386 | Z38: 11 | AA38: 81073649 | AB38: 0.23508191
A39: YP_001225782.1 | B39: SynWH7803_2059 | C39: MIEPTTIPVRRLPRYGFHTHTERLNGRAAMLGFIALLAVEIKLGHGLLIW | D39: high light inducible protein | E39: Photosynthesis | I39: -1.1353351 | J39: 0.50002304 | K39: 1 | L39: 528820.92 | M39: 0.0067448944 | N39: 1 | O39: 503316.99 | P39: 0.0064758226 | Q39: 3 | R39: 798743.26 | S39: 0.010337226 | T39: 1 | U39: 575102.86 | V39: 0.0073229336 | W39: 1 | X39: 532507.46 | Y39: 0.0066329039 | Z39: 2 | AA39: 625550 | AB39: 0.0079083886
A40: YP_001224263.1 | B40: SynWH7803_0540 | C40: MAISRGDMVRIKRPESYWYNEVGKVASIDTSGIRYPVVVRFEQVNYNGISGSEGGINTNNFAESELEPA | D40: photosystem I reaction center subunit IV | E40: Photosynthesis | I40: -1.140276 | J40: 0.54482622 | K40: 2 | L40: 1327434.8 | M40: 0.012268759 | N40: 2 | O40: 1155142 | P40: 0.010769849 | Q40: 2 | R40: 1023332.3 | S40: 0.0095969751 | T40: 1 | U40: 1336509.5 | V40: 0.012331972 | W40: 1 | X40: 764996.96 | Y40: 0.0069049196 | Z40: 2 | AA40: 1210987.8 | AB40: 0.011093962
...

Sheet R. pomeroyi
A1: Table S5B: Protein categories of R. pomeroyi proteins detected in SW co-culture with Synechococcus sp. WH7803
J2: Replicates
J3: A | M3: B | P3: C | T3: Category NAF
A4: Old NCBI reference | B4: New NCBI reference | C4: Annotation reference | D4: CDS sequence | E4: Annotated function and designation | F4: Assigned function | G4: Additional information for category assignement | I4: Assigned category | J4: SC | K4: Peak area | L4: NAF | M4: SC | N4: Peak area | O4: NAF | P4: SC | Q4: Peak area | R4: NAF | S4: NAF Average | T4: A | U4: B | V4: C
A5: YP_168626.1 | B5: AAV96656.1 | C5: SPO3430 | D5: MKTEGNTMKKVLFATTALIATASVAAADVRISGYGRFGLDYNDANDRAVNGVSKTTITSRLRLQFDMSAETDAGVAFDARFRAQAESRDNTPGGATFNGARFGVSYQGFRVNVGNIIGAVENMPGTYLETRTAGIGIDGASFYSHVGNVNNEFFNWDAYSSAGTGVNGIEAIYSTGGFTGHLSYSTRNGAVASDRIGVMLSYNFGDWTVAAAHQSSDAMWEDKTLVSVAWDGGQFGARVAYADNDGISKFGIYGNMDIGASSNILLFYTDEEAVSASDVLAGRGDNRDAVAGSNMNEGGSYGIHYSYDLGGGASFEAGYRRASNDNDTFQAGVYFSF | E5: outer membrane porin | F5: Membrane transport | J5: 104 | K5: 8.8840382e+08 | L5: 11.422265 | M5: 90 | N5: 9.853477e+08 | O5: 11.618864 | P5: 91 | Q5: 8.1965544e+08 | R5: 10.973689 | S5: =AVERAGE(L5,O5,R5) -> 11.338273 | T5: =SUM('R. pomeroyi'!L5:L102) -> 32.447432 | U5: =SUM('R. pomeroyi'!O5:O102) -> 33.744926 | V5: =SUM('R. pomeroyi'!R5:R102) -> 31.268801
A6: YP_165781.1 | B6: AAV93836.1 | C6: SPO0519 | D6: MSDIAPKLGPIEGDSSFEIRSGANVCRSNRSGTGVENQEEVKMKKSVFLGALTVAGMAAGVAAAGTMDDVKARGKLNCGVTTGLVGFAAPDSNGEWKGFDVALCRAVAAAVLGDGNAVEFVPTTGKTRFTALASGEVDMLARNTTWTFSRDVDLKFEFVGVNYYDGQGFMVPKSLGVSSAKELDGATVCIQTGTTTELNLADFFRANNISYEPVPIETNAEAQQQYLAGACDVYTTDASGLAATRATFENPGDHVLLPEIISKEPLGPLVRHGDHEWGDVVRWTLNALVSAEEMGITSANIDEMSAGTNNPEINRILGSEGTLGEMLGLDAEWAKRAIKVGGNYGEVFAQNIGESTPIGLARGLNAQWTDGGLLYSPPFR | E6: glutamate/glutamine/aspartate/asparagine ABC transporter, periplasmic substrate-binding protein | F6: Membrane transport | I6: Amino acid transport and metabolism; Signal transduction mechanisms | J6: 43 | K6: 2.8561293e+08 | L6: 3.2566116 | M6: 44 | N6: 3.5543849e+08 | O6: 3.7169348 | P6: 37 | Q6: 2.5357543e+08 | R6: 3.0107508 | S6: =AVERAGE(L6,O6,R6) -> 3.3280991 | T6: Average= | U6: =AVERAGE(T5:V5) -> 32.487053
A7: YP_168022.1 | B7: AAV96055.1 | C7: SPO2814 | D7: MSNKECSMKLKTLLMGAIASAALAPAAFAERGSDGNVSIIYWQAPSILNPFLSGGTKDVESASLVIEPLARYDENGGMVPFLATEIPTVENGGVSADLTSITWKIAPGIKWSDGSAFTAHDVKFTADYCMHPEGGCAQLTKFEGVTSVEALDDMTVKVTFDKPTPFPYGPFVGGESPIIQKAQFENCMGAKAPECTTENFGPIGTGPFVVTEFKPNDVITMKANDNYRDPAKPAFATLTFKGGGDATAAGRAVMETGEFDYAWNLQLAPEVIQQMQAGGKGTPVAGFGPLVERIMLNQTNPSPALPEGERSTAKHPHPFLQDPAVYKAMSMAIDRPLLVEIGYGQAGKVTCNWVPAPAAVNSDTFTCDTQDIEGAKKLLDDAGIVDTNGDGVREKDGVPLKVVYQTSTNAVRQDFQALIKEWWAEIGIESELRNINASVFFGGDPGSPDTFQKFYADVEMYANTFNGTDPQSYLANGLCDKAPKPESQWQGENISRFCNEEYDALHAELTKTAGAEARAEIAKRLNDIMVENGGMIPLVHRGRLSAHSNTLGGVVLNVWDSELWNAADWYRIK | E7: peptide/opine/nickel uptake ABC transporter periplasmic substrate-binding protein | F7: Membrane transport | I7: Amino acid transport and metabolism | J7: 63 | K7: 3.8412053e+08 | L7: 2.9045884 | M7: 60 | N7: 4.3534906e+08 | O7: 3.0191665 | P7: 58 | Q7: 3.774944e+08 | R7: 2.9723992 | S7: =AVERAGE(L7,O7,R7) -> 2.9653847 | T7: Dev= | U7: =STDEV(T5:V5) -> 1.238538
A8: YP_166784.1 | B8: AAV94830.1 | C8: SPO1543 | D8: MNALNRLLSSAVLGAAVLMTAPAPMAMAETPPNMLVIAHRIDDITTLDPAESFEFAGSDLSRNVYMRLVNFDPMDLKAGYQPEIAESWTVSEDKRSITFTIREGLKFHSGNPVRAEDVEFSLQRAVILNKTPAFILTQFGFTAENAAETIKAEGNTVTITTDKPYATSFVLNCLTAVIGGIVDKEVVMANEQDGDMGNTWLKTNTAGSGAYKLVSWKPNESITIQSNPDYYRGAPAMERVIVRHVQESASQRLLLERGDIDIARNLNPEDIAGARNAEGVKIDEELKGRLMYVSLSQKHPELSKPQVRQAFKYLVDYEGMKNSFLSGQYTIHQNFLPQTYLGASDAAPFTYDVEKAKALLAEAGIPEGMEIEVGVREAQERIEIAQSLQNALGQVGIKMNITIGTAKQILSRYRARELDVYLGAWGPDYPDPHTNAGTFAYNPDNSDAAQATGLLAWRNSWDTGGLTAKTDAAVVENDRDMRAKMYEEIQAEFRETSPFVIMFQQIEQSAQRDNVMNFSTGQAITSASYWQVTK | E8: peptide/opine/nickel uptake ABC transporter periplasmic substrate-binding protein | F8: Membrane transport | I8: Amino acid transport and metabolism | J8: 61 | K8: 3.051764e+08 | L8: 2.4761754 | M8: 61 | N8: 3.1687315e+08 | O8: 2.3580242 | P8: 58 | Q8: 3.0116128e+08 | R8: 2.544539 | S8: =AVERAGE(L8,O8,R8) -> 2.4595795
A9: YP_167412.1 | B9: AAV95453.1 | C9: SPO2187 | D9: MSAQKSNGSFNMNRNSKLGLGALVTAAFLAPAAMAEEFITIGTGGVTGVYYPTGGAVCRLVNKGRKEHGVRCSVESTGGSVYNINTIREGELEFGVAQSDWQYHAYNGTSKFEEAGKFENLRAVFSIHPEPFTVVARADAGITSFDDLKGKRVNIGNPGSGQRGTMDVVLEAKGWTTGDFALASELKAAEQSAALCDNQIDAMIYTVGHPSGSIQEATTACDSVLVNVDGEAIDKLVADNSFYRKATIPGGMYRGNDGDTTTFGVGATLVTSADVSEDAVYALVKAVFDNFEDFKKLHPAFANLTEAEMIKDGLSAPLHSGAEKYYRERGWIN | E9: TRAP transporter solute receptor TAXI family protein | F9: Membrane transport | I9: General function prediction only | J9: 35 | K9: 1.2379755e+08 | L9: 1.6107922 | M9: 35 | N9: 1.4940714e+08 | O9: 1.7829173 | P9: 36 | Q9: 1.1125883e+08 | R9: 1.507445 | S9: =AVERAGE(L9,O9,R9) -> 1.6337182
A10: YP_165903.1 | B10: AAV93956.1 | C10: SPO0648 | D10: MKFTSLLASAAMALGLATGAMADDKTKVGFVYVGPVGDGGWTYEHDKGRQAVEAEFGDKVETVFVESVPEGPDAERVMTQMALEGADLIFTTSFGYMDPTINVAKKFPKVKFEHATGYKQAENVSVYSARFYEGRAVQGTIAGRMTKSNIVGYIGSYPIPEVIRGINSAFIHARKVNPDVQFKIVWAYTWFDPAKEADAAKVLIEQGADVILQHTDSTAPQAAAQAAGNVITFGQASDMSEYAPMPRVSSIIDNWAPYYIARTKAVMDGTWTSVSTWDGIGAGMVGIGEISDAVPADVKAEALALKDALANGSYHAFTGPLKKQDGSDWLAAGETADDGTLAGMNFYVEGIEGDIPN | E10: bmp family protein | F10: Membrane transport | G10: periplasmic binding protein | I10: General function prediction only | J10: 25 | K10: 84463689 | L10: 1.0251172 | M10: 23 | N10: 91228766 | O10: 1.0154713 | P10: 21 | Q10: 77284157 | R10: 0.97672768 | S10: =AVERAGE(L10,O10,R10) -> 1.0057721
A11: YP_167786.1 | B11: AAV95821.1 | C11: SPO2573 | D11: MDRRSFLKTSAMGGAAAAATTALAAPAYAQGKRTLTMVTTWGRGLAGVHDSAQRVADNITAMSDGNLTVDLKAAGELVGAFEVFDAVSSGQADMYHGADYYFVGQHPGYAFFTAVPFGMTAQELVNWYYHDGGHELHDELGQIFGLKSFLAGNTGAQAGGWFSKEINGPEDFNGLKFRMPGLGGKALGKLGASVQNIPGSEVYQALSSGAIDGTEWIGPWADEKAGFQEITKTYYTAGFHEPGAGLSVATNREVFESLSPAHQKIIEVAAGECHQWNLAQFLSNNGSALQRLQAGGVKVLEFPDSVWDAFGKASQDVMAENMGDELFKKIHDSAMASMKSSSAWLNMSSGVYTAQRDRVLG | E11: solute-binding family 7 protein | F11: Membrane transport | G11: solute binding proteins | I11: Secondary metabolites biosynthesis, transport and catabolism | J11: 26 | K11: 74683857 | L11: 0.8963781 | M11: 28 | N11: 94955508 | O11: 1.0452424 | P11: 23 | Q11: 70833157 | R11: 0.88527996 | S11: =AVERAGE(L11,O11,R11) -> 0.94230017
A12: YP_166898.1 | B12: AAV94944.1 | C12: SPO1659 | D12: MTKAIIDAGRNLLRNGCMGTPEFHRTGPGLQRRTGRSTVRGPTANRKSHRETFMTTYETRQQPVHWAAEMHAQEFRDGKLSRREFLTRATGLGVSAAAAYGLIGLTAPTPAAASEAKQGGTLRVQMNVRELKDPRTYDWSELGNETRGTMEYLVEYNSDGTFRGILLESWEINDDATVYTLNVRKGVKWNNGDDFTAEDVARNIARWCDKSSETNSMAGRFASLIDADSGQAIDGAIEVVDSHTVRLNLPNSDISLIAGMSDYPAAIVHSSFSESDLTNNVGTGPYVIELLEVGVKCVLVRNENHTWWGEAVFGRPALDRIEYIDYGTDPSAWLSALESDEVDMLHESVGEFIDVMDGLGYAKSEVVTMSTVVVRPNQLAEVDGKKPYADKRVRQAISLAVDNAICLELGYGGRGAPAENHHVGPSHPEYAELPARKHDPAAAKALMEEAGMMDFEHEIHSIDDDWRRNTTDAVAAQLRDAGFKVKRTVLPGSTFWNDWTKYPFSSTNWNHRPLGVQIWALAYRSGEAWNEFGWANPEFDAILSEALALADADKRREVVARGQALIQEEGVTIQPYWRALYRHMKEGLVGTDMHIAFEHHHYKWGWAA | E12: oligopeptide/dipeptide ABC transporter, periplasmic substrate-binding protein | F12: Membrane transport | I12: Amino acid transport and metabolism | J12: 23 | K12: 1.1213438e+08 | L12: 0.79911063 | M12: 24 | N12: 1.157836e+08 | O12: 0.75674151 | P12: 28 | Q12: 1.0615469e+08 | R12: 0.78774718 | S12: =AVERAGE(L12,O12,R12) -> 0.78119977
A13: YP_166457.1 | B13: AAV94506.1 | C13: SPO1210 | D13: MLNSSRRGALRSAVGAMVIGLGLTFSGSATQAETVLKAVPHSDLKILDPIWTTAYITRNHGYMVYDTLFSLDAQGNIQPQMVDTVTTSEDGLMVTMTLRDGLVWHDGAPVTAADCVASINRWGSKDAMGQKMMSFVESLEATDDKTITFKLSTPTGLVTLALAKPSSNVPFMMPERVASTPSSEQIADYTGSGPFVFRQDLWEPGTKIVYEKFDGYVPRSEPASGLSGGKIAKVDVVEWLPIRDHQQAVNALKAGEIDFIEAPPHDLLPLLKDDPNITLDDFNPAGNQFTFRFNVLHPPFDNPKMRQALLYAFNQEDFVQAVVGNEEYYELCLALFGCGLPFESTAAMDGLLESNFAKARELIAESGYNGEPILLMHSTDLAVLTNLAPVAKDLMEAVGLNVDMQSMDWQTLVARRSKRDAPADGGWNAFITSWTTGDLFNPVAAAFLNSSCDTALFGWPCDTRIEELRDAFARATSVEEQKKIVDEVQAAWFDYPTHIHLGQWTSRAAMTNNVSGLLQTGAAVFWNLEKN | E13: oligopeptide ABC transporter, periplasmic oligopeptide-binding protein | F13: Membrane transport | I13: Amino acid transport and metabolism | J13: 29 | K13: 81554946 | L13: 0.66546847 | M13: 28 | N13: 89880884 | O13: 0.67263102 | P13: 26 | Q13: 73759392 | R13: 0.62672071 | S13: =AVERAGE(L13,O13,R13) -> 0.65494007
A14: YP_167817.1 | B14: AAV95852.1 | C14: SPO2606 | D14: MTTRRKFITTAAVGAAAAPLATPALAQSTIKWRMQTYAGPALAAHVIDPAIAMFNKIAGDRMQIELFYADQLVPTGELFRAMQRGTIDAVQSDDDSMASPTEVTVFGGYFPFASRYSLDVPVLFNQYGLNEIWDAEYSKVGVKHISAGAWDPCHFATKDPINSLADLNGKRVFTFPTAGRFLAQFGVVPVTLPWEDIEVAVQTGELDGIAWSGITEDYTVGWADVTNYFLTNNISGAWAGSFFANMDRWNELPEDLQTLFRVCCDQSHYYRQWWYWGGEASLRVNGTKMQLTSIPDAEWAQVEAAAVKFWDEIAAESETKAKVVEIFKKYNADMAKAGRPYRYG | E14: solute-binding family 7 protein | F14: Membrane transport | G14: solute binding proteins | I14: Secondary metabolites biosynthesis, transport and catabolism | J14: 24 | K14: 48673806 | L14: 0.61306788 | M14: 28 | N14: 50272617 | O14: 0.58073383 | P14: 22 | Q14: 42459233 | R14: 0.55688426 | S14: =AVERAGE(L14,O14,R14) -> 0.58356199
A15: YP_167051.1 | B15: AAV95093.1 | C15: SPO1814 | D15: MMNKMLSGAVAAALTVSFVGEAGATEWNVSVWGKRRAFTEHVEKLAELVSEKTGGAFTINVSYGGLSKPKENLDGISIGAFEMAQFCAGYHADKNRAITVLELPFLGVNTLAEEVAVSNAVYAHPAAQQEMAQWNARLLMTSPMPQYNLVGTGAPRDELAEFEGMRVRATGGLGAAFSAVGGVPTSVPATEAYNAMESGVVDTVAFAQHAHLSFGTINKADWWTANLNPGTVNCPVVVNIDAYEALSDDERAALDSSVDEAIAHYLTNYGALLKKWDDVLAEKGVEKVMISDAVLEEFRAKVAGPISAKWVEDMTAQGLPGQELLDLVHATLKAARGS | E15: TRAP dicarboxylate transporter, DctP subunit, putative | F15: Membrane transport | I15: Carbohydrate transport and metabolism | J15: 23 | K15: 34085067 | L15: 0.43693734 | M15: 21 | N15: 37529995 | O15: 0.44123086 | P15: 22 | Q15: 29499903 | R15: 0.39378134 | S15: =AVERAGE(L15,O15,R15) -> 0.42398318
A16: YP_168669.1 | B16: AAV96699.1 | C16: SPO3473 | D16: MKLKTALLATALTSAAFAVSAQEVTVMSWGGAYTKSQVEAYHKPFTAETGIKVNSVDADNPATPIKAQVEAGNVSIDVADVEFSDAVRLCDEGLLEEIDPAILSAAPDGTAATDDFIDGALQDCAVANIVWSTSVAYNTANVSMAPSSIADFFDTGKIPGKRGLRKSAKATLEMALMGDGVPANEVYDVLDTDEGVDRAFAVLDRIKSDIVWWEAGAQPPQLLADGEVVMSTAYNGRIFNAAVAEGQPFEIMWDGQILDFDLFVVPKGAPNKDAAMQFIAFSTSTQALADQAKWISYGPARKSSGALVGLYQDGKTEMAPHMPTSEAALKNALVNNFEFWVDKDAELNERFNAWLAN | E16: polyamine ABC trasnporter, periplasmic polyamine-binding protein | F16: Membrane transport | I16: Amino acid transport and metabolism | J16: 13 | K16: 30605071 | L16: 0.37144702 | M16: 19 | N16: 36738370 | O16: 0.40893638 | P16: 10 | Q16: 26658111 | R16: 0.33690883 | S16: =AVERAGE(L16,O16,R16) -> 0.37243074
A17: YP_166949.1 | B17: AAV94993.1 | C17: SPO1710 | D17: MKPAPMRKRFSAPREETSMNFLKTTLASSVVFAALCNAAMAAEDKIKVGVLHSLSGTMAISETTLKDTMLMLIEQQNAKGGLLGKQLEAVVVDPASDWPLFAEKARELLTVHEVDVIFGNWTSVSRKSVLPVIEELNGLLFYPVQYEGEESSKNVFYTGAAPNQQAIPATDYFLEELGVEKFALLGTDYVYPRTTNNILESYLKQKGIAEADIFVNYTPFGHSDWSKIVADVVALGADGKKVGVISTINGDANIGFYKELAAAGISADDIPVVAFSVGEEELAGLDTSNLVGHLAAWNYFQSAESDVNAEFVKSWKATMGEERVTNDPMEAHYIGFNMWVNAATEAGSTDVDAVRAKMYGQEFPNLTGGTAVMLPNHHLTKPVLIGEIQADGQFDIISQTAEVPGDAWTDFLPESAVLMSDWKELGCGMYNTETKTCVQTLSNY | E17: branched-chain amino acid ABC transporter, periplasmic substrate-binding protein | F17: Membrane transport | I17: Amino acid transport and metabolism | J17: 19 | K17: 41926450 | L17: 0.4091446 | M17: 20 | N17: 42999090 | O17: 0.38484014 | P17: 17 | Q17: 31242518 | R17: 0.31747848 | S17: =AVERAGE(L17,O17,R17) -> 0.37048774
A18: YP_167174.1 | B18: AAV95215.1 | C18: SPO1939 | D18: MKKLLTATAASALMASAAFAGGHAKEVKIGVILGFTGPIESLTPSMADGAELAMKEVTDSGLLLDGATVTSVRADSTCVDAAAATAAAERLVTSDKVDGIMGADCSGVTGAILSNVAVPNGVVMISPSATSPALSTADDNGLFFRTAPSDARQGVVMTEVLMEEGIKEVALTYTNNDYGKGLADSFQAAFEAAGGTVTISAAHEDGKADYSAEVGALAAAGGDRLVVAGYVDQGGSGIVRSAIDSGAFDTFHFPDGMIGAKLEENFGDEIEGSSGQHPGTDSPGVAKFSEMVGGAFDSTSPFTPEAYDAAALIMLAMQAANSKDSGDYKDHVMHVANAPGEKIYPGELAKALQIIKDGGEVDYVGATAVELIGPGESAGNYRQITIEGGKITTAKFR | E18: branched-chain amino acid ABC transporter, periplasmic substrate-binding protein | F18: Membrane transport | I18: Amino acid transport and metabolism | J18: 20 | K18: 31764671 | L18: 0.34667742 | M18: 24 | N18: 45431612 | O18: 0.45474896 | P18: 17 | Q18: 23457946 | R18: 0.26659421 | S18: =AVERAGE(L18,O18,R18) -> 0.35600686
A19: YP_165324.1 | B19: AAV93381.1 | C19: SPO0050 | D19: MPPASGPGALRNSCNRFGRARSFSLRPPHHERKRDMKHLVTALALLAATPALAQDKMTLLLDWFINPDHGPIIVAQEKGYFAERGLEVEIVAPADPSAPPRLVAAGQADLAVSYQPQLHLQIHEGLPLKRVGTLVATPLNCLLVLDNGPIKSPADLKGKKIGFSVAGVEEAILTTVLGKYDVALSDVEMINVNFSLSPALMSGQVDAVIGAYRNFELNQMDIEGEPGRCFYIEEEGVPSYDELIYVANPDRMDAGKIARFLEATEKATQFIVNNPQASWEIFSATSPELQDELNKRAWADTLPRFALRPAGFDAGRYARFETFLKDSGMIDSVNSVSAITIDVTAE | E19: ABC transporter, periplasmic substrate-binding protein | F19: Membrane transport | I19: Inorganic ion transport and metabolism | J19: 17 | K19: 28182370 | L19: 0.35291744 | M19: 19 | N19: 31099237 | O19: 0.35717225 | P19: 15 | Q19: 26524461 | R19: 0.34587702 | S19: =AVERAGE(L19,O19,R19) -> 0.35198891
A20: YP_167025.1 | B20: AAV95067.1 | C20: SPO1788 | D20: MSPFGTLPKGVRLIPYPTRSRTEPGQRNRQPTRSEIMKKLMNGAALALALAAGPALAADEVKLQLQWVTQAQFAGYYVALDKGFYDEEGLDVTILPGGPDIAPPQVLAGGGADAMLNWMPSALAAREKGLPVVNIAQPFKSSGLMLTCWKDTGITGPQDFKGKTIGVWFFGNEYPFLSWMSQEGISTDGGADGVTVLKQGFNVDPLLQRQADCISTMTYNEYGQVLDAGVSEDELVTFKYEDMGVATLEDGIYVLEDNLKDEAFKDKMTRFVRASMKGWKYAEANPDEAAGIVLDNDATGAQTEAHQVRMMGEIAKLTAGSNGALDPADFDRTVGTLLAGGSDPVITKTPEGAWTHEITDAALK | E20: ABC transporter, periplasmic substrate-binding protein | F20: Membrane transport | I20: Inorganic ion transport and metabolism | J20: 15 | K20: 29812689 | L20: 0.35487179 | M20: 14 | N20: 33651386 | O20: 0.36737165 | P20: 15 | Q20: 24999280 | R20: 0.30986845 | S20: =AVERAGE(L20,O20,R20) -> 0.3440373
A21: YP_165509.1 | B21: AAV93565.1 | C21: SPO0240 | D21: MIAFIKLLLELFFPLRNHPPVHEPREVDMTCKFLTLSASALVLTTGMAFAQTEIQWWHAMGGTNGERVDKIAADFNASQSEYKVVPTYKGNYTETMTAAVAAFRAKEHPHLVQVFEVGTATMMAAKGAIYPVEQLMSDAGEPFDKSDYLPAVISYYQTSEGELLSMPFNSSTPVLWYNADALKAAGVEVPKTWDDMKTAAKALVDSGMDCGFSFGWQSWVMIENYSAWHNIAMGTKENGFAGFDTELSFNNDEVTARLDDIAAMSEGNLFKYGGRRGDSLPMFTNGECGMWMNSSAYYGSIKGQAQFEFGQTMLPLDSAVADAPQNSIIGGATLWALAGHEAEEYKGLAKFMTYLSSPEVQAWWHQETGYVPITTAAYELSKEQGFYDSNPGTDTAIQQLSLNTPTANSRGIRFGNFVQIRDVINEELEALWAGDKTAAQALAAATERGNALLRKFERSAN | E21: SN-glycerol-3-phophate ABC transporter, periplasmic SN-glycerol-3-phosphate-binding protein | F21: Membrane transport | I21: Carbohydrate transport and metabolism | J21: 18 | K21: 27689573 | L21: 0.26024778 | M21: 21 | N21: 28653367 | O21: 0.24698968 | P21: 19 | Q21: 24776102 | R21: 0.24248411 | S21: =AVERAGE(L21,O21,R21) -> 0.24990719
A22: YP_167083.1 | B22: AAV95125.1 | C22: SPO1846 | D22: MKNMIKGLLAATALTAAAGLASAETQGVTDDEVVIGAVNDLSGIFAAVGVPATKGANVYFDKVNAAGGVHGRKIRYVVEDHGYQMPRAMQGFNKLLNRDKVFAMMQNLGTPMNLAGFKLIDPLGIPNIAPLSAARQMIQDPMQNKFTSFSSYFDQSVVGVKYLVAEYGAKNVCSMYLPTDFGKEILEGTKAGAEEAGAAFVAETTHKPDETDFVGSLSKLKESGCEIVTIALGVRQAITIVGTAKKMGLTDMQFMGTSASFLTVVAQVPGGVTEGFYAAASWQDLWARADEPAPKAFIEEYKAATGEDPQGFAMLGYAAAQQMVMALEAAGRDLTHESFIAAMESLDYQDDLVGNHINYGPDDHQGADSVYVLKVENGGWAKVHEE | E22: branched-chain amino acid ABC transporter, periplasmic substrate-binding protein | F22: Membrane transport | I22: Amino acid transport and metabolism | J22: 14 | K22: 18741240 | L22: 0.21036947 | M22: 13 | N22: 26878592 | O22: 0.276709 | P22: 15 | Q22: 20273091 | R22: 0.23696484 | S22: =AVERAGE(L22,O22,R22) -> 0.24134777
A23: YP_165661.1 | B23: AAV93716.1 | C23: SPO0398 | D23: MFAVFNPARKIALSAMALAAAALLSACEPVAIGGGGPSINTSKPVPVALLVPRGSAQSGDAVLAQSLENAARMAIADLQNVQIDLRVYDTAGDAGTAAAVAKQAVGEGAKIILGPVYAQAANAAGLAVLNQNVNVLSFSNNVNIAGGNVFVLGPTFNNSADRLVSFAARQGKGNIVVVHSTDEAGQLGRAAISDAISRSSAKLAGTVAYERSQQGVINSVPQVKATVDGTGADSVFFTSTTAGALPLYTQLLPEAGVSPAQTQFIGLTRWDIPAQTLELPGVQGGWFALPDPSKAAAFRARYQSTYGGAPHPIGGLAYDGIAAIGALVGAGKSDALTGAALTQSAGFQGVGGIFRLRPDGTNERGLAIATIQNKQVVVIDPAPQSFSGAGF | E23: hypothetical protein SPO0398 | F23: Membrane transport | G23: transport of lipid compounds | J23: 12 | K23: 21701095 | L23: 0.24047869 | M23: 14 | N23: 23575542 | O23: 0.23960121 | P23: 12 | Q23: 20202670 | R23: 0.23312199 | S23: =AVERAGE(L23,O23,R23) -> 0.23773396
A24: YP_168201.1 | B24: AAV96233.1 | C24: SPO2995 | D24: MPEGAKYANLDSSVNKNRAAKPRKHSTGENSMNEQLEHMAGRVTAGKMTRREFMGKAAALGVSAAVASSIFAQAAQAAGPKKGGVVKIGSVGGESTNSLDPATYASQVPYHNGRQFGDTLVEVASDGSIEHRLAESVEASADAKTWTFKLRQGVEFHNGKTMTSEDVLKTMQRHSNEDSKSGALGIMKGIESMKADGEYFSVTLTDANADLPYLMADYHLIIQPDGGMDNPGAGIGTGPYQVEVNEPGVRHAYKKFANYWGDDAHFDGVEVLVINDATARTAALQSGQVHMINRVEPKVASLLDRAPNLTVQSTPGRGHYVFIMHVDKAPFDNKDLRLALKYAINREEMVEKILRGYGSVGNDMPINAAYPLFDSAIPQREFDLAKAAEHYKASGHDGSPIILRTADGAFPGAVDAAALFQQTAAQAGIPLEIKREPNDGYWSEVWNVQPFCASYWGGRPVQDQMYSTAYLSTADWNDTKFKNADFDAMLMAARSELDPAKRKEIYSKMGMLLRDEGGLICPMFNDFVDAVSNTLSGWETDPNGELMNGQVTRKLWFS | E24: peptide/nickel/opine uptake ABC transporter periplasmic substrate-binding protein | F24: Membrane transport | I24: Amino acid transport and metabolism | J24: 22 | K24: 28355322 | L24: 0.22017707 | M24: 19 | N24: 33068044 | O24: 0.23549321 | P24: 20 | Q24: 24503740 | R24: 0.19812962 | S24: =AVERAGE(L24,O24,R24) -> 0.2179333
A25: YP_168487.1 | B25: AAV96518.1 | C25: SPO3291 | D25: MKMKLATVALGALMAAGPALADLTFPSLSYRTGPYAAGGIPFADGYADYFTLLNERDGGIGGVKANVLECETGYNTEKGVECYESTKGQGALVYQPLSTGITYQLIPKATADGIAIHSMGYGRTSAKNGNVFSHVFNYPANYWDGASGAVNYLLEINGGDIKGKKIALVYHNSAYGKEPIRTLEELSKKHGFDLSTLPVDHPGQEQKSQWLQIRRDKPDYVLMWGWGVMNQVAVQEAANIRFPMENFIGIWWSGSENDVLPAGDAANGYKALTFHNVGTAFPLFDDLQKYVIDAGKAAGAGDQVGTVLYNRGLYAAMLAAEAAKKAQEISGKADITAADMRDGMEALEMTEAKMAELGLPNFGPTFSVSCGNHGGDALVGVTQWDATSKTWSLISDFKPTDGDVIGALIEEDSSAYASENNISPRCN | E25: branched-chain amino acid ABC transporter, periplasmic branched-chain amino acid binding protein, putative | F25: Membrane transport | I25: Amino acid transport and metabolism | J25: 17 | K25: 22522018 | L25: 0.22853416 | M25: 15 | N25: 23212574 | O25: 0.21602275 | P25: 11 | Q25: 17608438 | R25: 0.18605623 | S25: =AVERAGE(L25,O25,R25) -> 0.21020438
A26: YP_168981.1 | B26: AAV97007.1 | C26: SPO3787 | D26: MPIREERMKNSSQIMTNPTRRAFLQNSSAAAAAAGFGGIGSFIASPVFASDYAPGMTGGPTGFEGAERFQYNNTMSEGRAIEGIKALQAAGNAPAKISMLLTDGAIGQITKPFPEGGPSAKEVWERETGIEIDIVGAPAEDIFKKVMQDVTTGGGTFDIYTGPWNSTGDLVSSGGAVNCSDFVAKYQPDWADPERGTPTPEMEKLLYTYAGDYYSFSLDGDFQTWFYLKGLYEDPRVQDAFLSETGVALKTPDTWEEVDRISKFFTGKDFGNGPMYGNGNLMSPFWGLATFYARFASMDFPNYHFFDEDGNPNLNSDLGIQCAEEHVRSFEWCPPDALTFTWAEAYATMWNLQIPHTAIYTNLVKFGDGYNADGTPKSKATGMIGSHLPVGRRFGDQLNRRSVLYYHITAWISSQSQHPEAVYLFLQWLSSTRTYTWMAGNPGGYFDPMQQANFKEPLVASTYHPYAMETIPQTIARSVPSINFAGQTALDNALDEEIQAAITGQKSAREAMDAAQSKWERIIKRQKRNGIVDAIKASRATWPTIVDPA | E26: sugar ABC transporter, periplasmic sugar-binding protein | F26: Membrane transport | I26: Carbohydrate transport and metabolism | J26: 18 | K26: 23934682 | L26: 0.18889785 | M26: 21 | N26: 24390286 | O26: 0.17654224 | P26: 17 | Q26: 24547147 | R26: 0.20173438 | S26: =AVERAGE(L26,O26,R26) -> 0.18905816
A27: YP_165784.1 | B27: AAV93839.1 | C27: SPO0522 | D27: MSELAIDREIDRSKMQVSDEVAIEITNMNKWYGAFHVLRDINLTVYQGERIVIAGPSGSGKSTLIRCLNALEEHQQGKIVVDGTELSNDLKNIDKIRSEVGMVFQHFNLFPHLTILENCTLAPIWVRKTPRKEAEETAMHFLEKVKIPEQALKYPGQLSGGQQQRVAIARSLCMRPRIMLFDEPTSALDPEMIKEVLDTMIELAEEGMTMLCVTHEMGFARQVANRVIFMDAGQIVEQNEPEEFFNNPQSERTKLFLSQILGH | E27: glutamate/glutamine/aspartate/asparagine ABC transporter, ATP-binding protein | F27: Membrane transport | I27: Amino acid transport and metabolism | J27: 8 | K27: 9328749.8 | L27: 0.1536878 | M27: 10 | N27: 12229089 | O27: 0.18477468 | P27: 8 | Q27: 9571780.9 | R27: 0.1642057 | S27: =AVERAGE(L27,O27,R27) -> 0.16755606
A28: YP_165960.1 | B28: AAV94012.1 | C28: SPO0706 | D28: MKRILLSGVAALALPGAALAACPAVTVADPMGVAAGTFPQQYDLAEFQSAAGCTMDFAENPAIGDLNARIKGNPALPPLAERLPSEPLVVAPYDGIGQYGGQFDALSNATESGTSDFLSVRHVNLFRYSDDLQTVVPNVAKSWEWNEDFTQLTVHLRAGHKWSDGAPFTAADVVFWYDNLMMDTNVMAEPKDYALAGGKPMKVEAVDDTTVRFTLEAPKPGLIETFSFTYVQPFQPKHFFGQFHPALDANADANAQALGYENGYDLIKAYYGNSDWMDTPSPMLTAGDKLAGLPKDTMPTLESHILVKETTEGRHYVANPYFFQVDTAGNQLPYISNMDETYVGDEEVRTLKLLNGEVDYKSQAVNLTQAPVLLEGQEKGNYTIDVKPGIASATLTFNVTSEDLGKRAIFNDVRFRAAMSVAIDRDQLNEVVAFGLGTPNQYIGFSPRPDFIDAKWESHEIAFDPDRARALLDEVGLVDKDGDGDRDLPNGDPFVLDWQFSTQASSSQLVELIAQNWTDVGVTTTIKEVTSDEYRSSQSSNTLDVMMWGKGQPAGSILGDGEIWVPPFDGYFDVRTGMLWAEWISSNGSAGVEPPAWVAELKSELDTYQSSAPGTETSIAAAQKMVEIMTGQVLFIGTINAPAPVYHSNKLKNFPEFKTQSYEFYRTYPYRPAQWWLSE | E28: oligopeptide ABC transporter, periplasmic oligopeptide-binding protein | F28: Membrane transport | I28: Amino acid transport and metabolism | J28: 16 | K28: 25641770 | L28: 0.1636251 | M28: 15 | N28: 25687379 | O28: 0.15033292 | P28: 15 | Q28: 25445365 | R28: 0.16907919 | S28: =AVERAGE(L28,O28,R28) -> 0.1610124
A29: YP_168665.1 | B29: AAV96695.1 | C29: SPO3469 | D29: MTFKSLTLTAVVALASSTAFAEEVRVYNWSDYIDEELLAKFEAETGITLIYDVFDSNEVLETKMLAGGSGYDVVVPTGTFLQRQIQAGAFQKLDLSKLPNHANMWDQIESRTAQYDPGNEYSINYMWGTTGLGVNVGKVREVLGEDAPMNSMDLVFNPENMEKLASCGVHFLDAPTELIPATLKYLGENPDSHDADVIAKAEPVLMAVRPYIQKFHSSEYINALANGDICVAIGWSGDILQARDRAAEADNGVEIEYHAFKQGSLMWFDQMAIPVDAPNPDAAHVFLNFIMDAQNMAAASNYVYYANGNKASQEHLVEDVIGDTAIYPDAETMDNLYTTTPYPAKIQRTVTRLWTKVKSGT | E29: putrescine ABC transporter, periplasmic putrescine-binding protein | F29: Membrane transport | I29: Amino acid transport and metabolism | J29: 12 | K29: 13745428 | L29: 0.16497676 | M29: 9 | N29: 16328490 | O29: 0.17973924 | P29: 7 | Q29: 10749934 | R29: 0.13435376 | S29: =AVERAGE(L29,O29,R29) -> 0.15968992
A30: YP_166078.1 | B30: AAV94130.1 | C30: SPO0825 | D30: MSLAACPTGGPPRQRPEQPARLRPTDQPEGNDMTLIRRTVLGALAALPLAALTPQIARAADTIVLGEVNSYTRLPAFTEPYKKGWELAIEQINAAGGVLGKDLVVVSRDDTGDPATAIRIAEELIAKEGAVMIFGTFLSNIGLAVADFANQKQVFFLASEPLSDALVWSKGNKYTYRLRPSTHMQAAMLAEQAAKLDAVKWATVAPNYAYGQDAVAAFKAELTRLRPDVQFVEEQWPPVFKIDAGPTVRAIEAAKPDAIYNVTFGGDLAKFVREGSLRYLFDDRPVVSLLTGEPEYLEPLQGETPNGWIVTGYPSTDIDTPEHKAFAEAYIAKFGEAPKTGSIVGYNSVLSIAAAITKAGSTETEAMLAAMEGLEVSSSPTGPFMFRAADHQSTMGAYVGKTALVDGQPKMVDWFYADGAAYLPSEEEAAKLRPAE | E30: branched-chain amino acid ABC transporter, periplasmic substrate-binding protein | F30: Membrane transport | I30: Amino acid transport and metabolism | J30: 14 | K30: 15781170 | L30: 0.15682829 | M30: 16 | N30: 15925211 | O30: 0.14514524 | P30: 17 | Q30: 14318297 | R30: 0.14816858 | S30: =AVERAGE(L30,O30,R30) -> 0.15004737
A31: YP_167361.1 | B31: AAV95402.1 | C31: SPO2133 | D31: MARSRTMKLLVPALVAVSMAAAPAMAGDWSGAYLGLGVGYGDADGPGARDGEAASFGGHIGYNFDLGNRFVMGGELEYDRVNNDLGAGGGTLDEIGRLKVKAGYDFGPVLGYGVLGAARATSTFGNENGLVYGLGLAMPVTDYLSVSGEVLRHQFKDFGGAGNDFDVNTFNLRASLRF | E31: outer membrane protein, putative | F31: Membrane transport | J31: 2 | K31: 6255119.8 | L31: 0.15226053 | M31: 2 | N31: 6181927 | O31: 0.13800917 | P31: 2 | Q31: 5337239.2 | R31: 0.13528446 | S31: =AVERAGE(L31,O31,R31) -> 0.14185138
A32: YP_168668.1 | B32: AAV96698.1 | C32: SPO3472 | D32: MYGELALTTRTSSDTFVEFERVQKSYDGETLVVKDLNLTMPKGEFLTMLGPSGSGKTTCLMMLAGFETATHGEIKLDGRPINNIPPHKRGIGMVFQNYALFPHMTIAENLSFPLEVRKIGKSDREAKIKRALDMVEMGAFGGRRPAQLSGGQQQRVALARALVFEPELVLMDEPLGALDKQLREKMQFEITRLAHELGITVVYVTHDQTEALTMSDRVAVFNDGVIQQLAPPDELYEQPANSFVAQFIGENNTLEGEVQEIRDGIAVVRLDDGGLIDCKPVNVSRPGERTRVSIRPERVEFNKSRLQKGVHTLKAEVMEFIYMGDIFRTRVRVAGNDEFIIKTRNAPDQVRLEPGAQIEIGWLPEDCRALDA | E32: polyamine ABC transporter, ATP-binding protein | F32: Membrane transport | I32: Amino acid transport and metabolism | J32: 14 | K32: 11562911 | L32: 0.13467778 | M32: 13 | N32: 13934892 | O32: 0.14885545 | P32: 13 | Q32: 11216357 | R32: 0.13603796 | S32: =AVERAGE(L32,O32,R32) -> 0.13985706
A33: YP_165642.1 | B33: AAV93697.1 | C33: SPO0379 | D33: MTLMKSLMGAAAAMALTAGAALAEPALIFDLGGKFDKSFNEAAFNGAQRWAEETGGSFREIELQSEAQREQALRRFAEAGANPVITMGFAMADPLSAVAADYPDTKFVAVDVTWLDAPNIRQIGFAEHEGSYLVGMMAAMASKSGTVGFVGGMDIPLIRHFGCGYAQGVKAVNPDVKIVANMTGTTPAAWNDPVKGSELTKAQISQGADVVYAAAGGTGVGVLQTAADEGILSIGVDSNQNHLHPGKVLTSMLKRVDVAVYDAMKAGENLETGVFNMGLAEEGVGYALDDNNAALISGEMKAAVDQARQDIIDGKLNVVSYYENDSCPALKF | E33: sugar ABC transporter, periplasmic sugar-binding protein | F33: Membrane transport | I33: General function prediction only | J33: 12 | K33: 11070335 | L33: 0.14447556 | M33: 13 | N33: 12731361 | O33: 0.15238451 | P33: 9 | Q33: 8919797 | R33: 0.12121828 | S33: =AVERAGE(L33,O33,R33) -> 0.13935945
A34: YP_165129.1 | B34: AAV97434.1 | C34: SPOA0300 | D34: MQRRSLMKAAMTAATLTAFGTTAALAENPVLKIGFVGVTSGPAAAWGISNQRSMETRAAWINETGGYTIGGTTYDIEIVSFDDQKDPKRAIAGMERMAQEGIHYVVGPNVDDGAAAVRPVAEANGIMYFPYAFPKELYQAPASNAVLGMVANYQSGPAIYKYLMEKEGVETVAFIAANESDPLSQRDGGVAAAEALGLKVVSSSVTYQVDTTDFTPVLTPVMRTQPDLLVLSGVSPANAPQLIRSARELGFQGLISTETAQDAGVLAEGAGDLANGFISVGGASTPELASPMMNEFVKRYTEMFGEYNDESNTKVYALEYILETLKANPAAIEDVAAFQATMDTFEAPNPYMNGDATLRYVGMTSFGQRRQVAVPLVVNVYQDGAFETLFVAAVD | E34: branched-chain amino acid ABC transporter, periplasmic branched-chain amino acid-binding protein | F34: Membrane transport | I34: Amino acid transport and metabolism | J34: 9 | K34: 11753085 | L34: 0.12892183 | M34: 8 | N34: 13201038 | O34: 0.1328052 | P34: 5 | Q34: 11954596 | R34: 0.13654916 | S34: =AVERAGE(L34,O34,R34) -> 0.13275873
A35: YP_167513.1 | B35: AAV95553.1 | C35: SPO2289 | D35: MTFARVAPRSSDATRAPRPGALIWKSDPSPPHQRARNLRFIHLMGKKMITTLRTTSALALAAAALAAPASAQLLYENQSGGSVRLYGQFNPALISVDDGQQTETQIRDNDLSRSRIGLRLAQPFGDNTFRFRFEAGLGLPNSTETNQLGDNFSGWTRDDLRHIDFSLEGDWGKVSLGQGSMAADGIAESDLSYVGVALYSYLADANAGFFFRDTAGVLSGPAVGDALDTFDGSRRGRIRYDSPEIAGFTFSAAYGENILNTADQSDYYDAAVRYSGEFAGGVQLDAGLAYQVRDNNGVDRSDVVGSASVLLKNGLSFTFAGGTRDNDAAGATDPDYLYFKVAYDVDLFSFGKTGVGVHYYDGSDFNVAGSETKGWGVGIAQRVEAYNTDVYFTYQDYEYDDAANSYQDLSTIVLGARWRF | E35: hypothetical protein SPO2289 | F35: Membrane transport | G35: Porin | I35: Cell wall/membrane/envelope biogenesis | J35: 11 | K35: 12882332 | L35: 0.13289753 | M35: 10 | N35: 13555078 | O35: 0.12824983 | P35: 9 | Q35: 10806952 | R35: 0.11609277 | S35: =AVERAGE(L35,O35,R35) -> 0.12574671
A36: YP_166639.1 | B36: AAV94685.1 | C36: SPO1398 | D36: MLEKITRYLHCRREIVPTRPRTAPVPTAYRIRRKRFSMQTGPLSFSKRLHWIPAMALAFGLNTVQLDAQQAAPKVSVAAAYSKEITEEAVFIGRGEAIDKVDIVARVSGFLDEQLVEDGSTVAEGDLLFRIEPDLYQAVLEARRADLDKAEANLELAGVELARKEELLRREATPASEVDIARANELVAEAAVKSAKAAIRQAELDLSYTEIDAPFAGRLGRVATSVGDVVGPANPPLVTLVRETPIHVTFALNEKRLVDVLQQLGETAETLAESQRSPEVHVTLPNGTPLGETGRLVFVDNRIDPLTGSVVMRAEFANTGRLIVDGAFVHVRISALKPTLRVLVPQAALQRDQRGDFVLVVNDKQMVEQRYVTLGDTVGTAAIVLEGLREGESVIVEGLQRVRPGVAVDAVVAAEQPGE | E36: RND family efflux transporter MFP subunit | F36: Membrane transport | G36: RND family efflux transporter | I36: Cell wall/membrane/envelope biogenesis | J36: 19 | K36: 11139647 | L36: 0.11519381 | M36: 19 | N36: 14569318 | O36: 0.13817493 | P36: 16 | Q36: 11304418 | R36: 0.12172658 | S36: =AVERAGE(L36,O36,R36) -> 0.12503177
A37: YP_168010.1 | B37: AAV96043.1 | C37: SPO2802 | D37: MREKIDCSVKKCSASRKKQERIMKNTSITRRVMLAAAVAASALMTAGAAAAEKVKVAAIYTLPVEQQWISRIHKALNTAADRGDIVYAFSENVANTDYERVMREYAEQGVQLIVGEVFGLERAARKVAKDYPDTAFLMGSSFGPVAPNFSVFDNWIHEPSYLTGMVAGAATESNVIGMVGGYAIPEVNRLMHAFMDGARSVNPDVRFIVNFIDSWYDPPKAKESAFAMMDAGADVMYAERFGVSDAAVERGVKAVGNVIDTSGDYPGTIVASALWHMEATIDKAIANVAGGSFEAADYGQYSFMAYGGGSLVLDESLVAPETVAAVRAKEAEILDGLFRVNVNDDRPVSDN | E37: bmp family protein | F37: Membrane transport | G37: periplasmic binding protein | I37: General function prediction only | J37: 10 | K37: 9368429.9 | L37: 0.11564621 | M37: 12 | N37: 12547805 | O37: 0.14205768 | P37: 10 | Q37: 9011141.4 | R37: 0.11583077 | S37: =AVERAGE(L37,O37,R37) -> 0.12451155
A38: YP_167545.1 | B38: AAV95584.1 | C38: SPO2322 | D38: MQCHGSAHRFPEISRGCSPSLSTKECPMDGGAIAQFLPLILIFAIMYLLLIRPQQKKVKEHQAMVSALRRGDQVITQGGLIGKVAKVKEDGEIEVEIAEGVKVRVVKSTIAQVLNKTEPAN | E38: preprotein translocase, YajC subunit | F38: Membrane transport | I38: Intracellular trafficking, secretion, and vesicular transport | J38: 3 | K38: 2941036.3 | L38: 0.10531415 | M38: 3 | N38: 4232630.7 | O38: 0.13900457 | P38: 2 | Q38: 3238207.2 | R38: 0.12074537 | S38: =AVERAGE(L38,O38,R38) -> 0.12168803
A39: YP_166486.1 | B39: AAV94533.1 | C39: SPO1240 | D39: MLRTLTGRLSRMAVLAAGVAVIAIAPRPAVADNLADALIGAYNTSGLLEQNRALLRAADEDVAIALSALRPIVNWTARIQTTYNRSGNAIASTTATPDTFFAGLELTQLLYDGGAARLGRQAAQETVLATRQALVQIEQQVLFRAVTAYLNVLLQEETVGIRQNNVRLLGEELRASQDRFEVGEVTRTDVALSESRLANARANLADANGALTTAHAEYINAVGRHPGRTTGQPAMPGLPRSEDDAAALALRNHPSLIGAQHQVRALDLVVGQQRANLGPNVRFQAELGFTDDFGGTTFNDSASASVIYSQPLYAGGRLNASVRRAMAQRDASRANLLNVQRNVTQDVSNAYVRFQTANASLTASAERVRAAQVAFDGIREEATLGARTTLDVLTAEQDLLDAQLARISARTERSLAAYQLLASQGLLTAERLGLAVQIYDPTLYYNMVKDAPAAISKRSRDLDRVLEALGKK | E39: TolC family type I secretion outer membrane protein | F39: Membrane transport | G39: type I secretion outer membrane protein | I39: Cell wall/membrane/envelope biogenesis; Intracellular trafficking, secretion, and vesicular transport | J39: 15 | K39: 12065424 | L39: 0.11075728 | M39: 13 | N39: 11593093 | O39: 0.097602598 | P39: 13 | Q39: 12021308 | R39: 0.11491083 | S39: =AVERAGE(L39,O39,R39) -> 0.1077569
A40: YP_168312.1 | B40: AAV96344.1 | C40: SPO3109 | D40: MMRFLTSLVLGAALLAGAAQAQNQPLRITIDEGIIEPLPYAAPNFVPDSPAAAEYAAEIARVLAADLTGSGLFREIPSTAYISQVTSFDAPVQFADWKAINAQALITGAVSVSGNRLTVRFRLWDVFAGAELGSGLQFAGTTDGWRRMSHKVADAVYSRITGESGYFDSRVAFVSESGPKDQRRKRLAIMDYDGANVQYLTDSSSIVLAPRFSPTGDRVLYTSYQGGFPRIHILDVGQVQQRVLQSQDGTMSFAPRFSPDGQTVLFSLAQGGNTDLYAMNIASGQSTRLTSAPSIETAPSYAPDGSRIVFESDRSGTPQLYVMSAAGGEATRISFGQGRYGTPVWSPRGDLIAFTKQSKGRFHIGVMRADGSEERLLTASFLDEGPTWSPNGRVIMFTRETQGASGRAALYSVDISGRNLRPVRTPDGGSDPSWSPLQK | E40: translocation protein TolB | F40: Membrane transport | I40: Intracellular trafficking, secretion, and vesicular transport | J40: 15 | K40: 10222804 | L40: 0.10089676 | M40: 12 | N40: 12297276 | O40: 0.11131366 | P40: 11 | Q40: 10625845 | R40: 0.10920693 | S40: =AVERAGE(L40,O40,R40) -> 0.10713912
...
